2025-05-10 17:28:18|INFO    |waitress                        |BAZARR is started and waiting for requests on: http://***.***.***.***:6767|
2025-05-10 17:28:18|INFO    |root                            |BAZARR trying to connect to Sonarr SignalR feed...|
2025-05-10 17:28:18|INFO    |root                            |BAZARR trying to connect to Radarr SignalR feed...|
2025-05-10 18:24:32|ERROR   |root                            |BAZARR Error trying to get rootfolder from Radarr. Connection Error.|'Traceback (most recent call last):\n  File "/app/bazarr/bin/bazarr/../libs/urllib3/connection.py", line 198, in _new_conn\n    sock = connection.create_connection(\n           ^^^^^^^^^^^^^^^^^^^^^^^^^^^^^\n  File "/app/bazarr/bin/bazarr/../custom_libs/subliminal_patch/http.py", line 325, in patched_create_connection\n    return _orig_create_connection(address, *args, **kwargs)\n           ^^^^^^^^^^^^^^^^^^^^^^^^^^^^^^^^^^^^^^^^^^^^^^^^^\n  File "/app/bazarr/bin/bazarr/../libs/urllib3/util/connection.py", line 85, in create_connection\n    raise err\n  File "/app/bazarr/bin/bazarr/../libs/urllib3/util/connection.py", line 73, in create_connection\n    sock.connect(sa)\nTimeoutError: timed out\n\nThe above exception was the direct cause of the following exception:\n\nTraceback (most recent call last):\n  File "/app/bazarr/bin/bazarr/../libs/urllib3/connectionpool.py", line 793, in urlopen\n    response = self._make_request(\n               ^^^^^^^^^^^^^^^^^^^\n  File "/app/bazarr/bin/bazarr/../libs/urllib3/connectionpool.py", line 496, in _make_request\n    conn.request(\n  File "/app/bazarr/bin/bazarr/../libs/urllib3/connection.py", line 400, in request\n    self.endheaders()\n  File "/usr/lib/python3.12/http/client.py", line 1333, in endheaders\n    self._send_output(message_body, encode_chunked=encode_chunked)\n  File "/usr/lib/python3.12/http/client.py", line 1093, in _send_output\n    self.send(msg)\n  File "/usr/lib/python3.12/http/client.py", line 1037, in send\n    self.connect()\n  File "/app/bazarr/bin/bazarr/../libs/urllib3/connection.py", line 238, in connect\n    self.sock = self._new_conn()\n                ^^^^^^^^^^^^^^^^\n  File "/app/bazarr/bin/bazarr/../libs/urllib3/connection.py", line 207, in _new_conn\n    raise ConnectTimeoutError(\nurllib3.exceptions.ConnectTimeoutError: (<urllib3.connection.HTTPConnection object at 0x7e82ac18d250>, \'Connection to ***.***.***.*** timed out. (connect timeout=60)\')\n\nThe above exception was the direct cause of the following exception:\n\nTraceback (most recent call last):\n  File "/app/bazarr/bin/bazarr/../libs/requests/adapters.py", line 486, in send\n    resp = conn.urlopen(\n           ^^^^^^^^^^^^^\n  File "/app/bazarr/bin/bazarr/../libs/urllib3/connectionpool.py", line 847, in urlopen\n    retries = retries.increment(\n              ^^^^^^^^^^^^^^^^^^\n  File "/app/bazarr/bin/bazarr/../libs/urllib3/util/retry.py", line 515, in increment\n    raise MaxRetryError(_pool, url, reason) from reason  # type: ignore[arg-type]\n    ^^^^^^^^^^^^^^^^^^^^^^^^^^^^^^^^^^^^^^^^^^^^^^^^^^^\nurllib3.exceptions.MaxRetryError: HTTPConnectionPool(host=\'***.***.***.***\', port=7878): Max retries exceeded with url: /api/v3/rootfolder?apikey=(removed) (Caused by ConnectTimeoutError(<urllib3.connection.HTTPConnection object at 0x7e82ac18d250>, \'Connection to ***.***.***.*** timed out. (connect timeout=60)\'))\n\nDuring handling of the above exception, another exception occurred:\n\nTraceback (most recent call last):\n  File "/app/bazarr/bin/bazarr/radarr/rootfolder.py", line 22, in get_radarr_rootfolder\n    rootfolder = requests.get(url_radarr_api_rootfolder, timeout=int(settings.radarr.http_timeout), verify=False, headers=HEADERS)\n                 ^^^^^^^^^^^^^^^^^^^^^^^^^^^^^^^^^^^^^^^^^^^^^^^^^^^^^^^^^^^^^^^^^^^^^^^^^^^^^^^^^^^^^^^^^^^^^^^^^^^^^^^^^^^^^^^^^\n  File "/app/bazarr/bin/bazarr/../libs/requests/api.py", line 73, in get\n    return request("get", url, params=params, **kwargs)\n           ^^^^^^^^^^^^^^^^^^^^^^^^^^^^^^^^^^^^^^^^^^^^\n  File "/app/bazarr/bin/bazarr/../libs/reque2025-05-10 18:33:28|INFO    |waitress                        |BAZARR is started and waiting for requests on: http://***.***.***.***:6767|
2025-05-10 18:33:28|INFO    |root                            |BAZARR trying to connect to Radarr SignalR feed...|
2025-05-10 18:33:28|INFO    |root                            |BAZARR trying to connect to Sonarr SignalR feed...|
2025-05-10 19:27:45|ERROR   |root                            |BAZARR Error trying to get rootfolder from Sonarr. Connection Error.|'Traceback (most recent call last):\n  File "/app/bazarr/bin/bazarr/../libs/urllib3/connection.py", line 198, in _new_conn\n    sock = connection.create_connection(\n           ^^^^^^^^^^^^^^^^^^^^^^^^^^^^^\n  File "/app/bazarr/bin/bazarr/../custom_libs/subliminal_patch/http.py", line 325, in patched_create_connection\n    return _orig_create_connection(address, *args, **kwargs)\n           ^^^^^^^^^^^^^^^^^^^^^^^^^^^^^^^^^^^^^^^^^^^^^^^^^\n  File "/app/bazarr/bin/bazarr/../libs/urllib3/util/connection.py", line 85, in create_connection\n    raise err\n  File "/app/bazarr/bin/bazarr/../libs/urllib3/util/connection.py", line 73, in create_connection\n    sock.connect(sa)\nTimeoutError: timed out\n\nThe above exception was the direct cause of the following exception:\n\nTraceback (most recent call last):\n  File "/app/bazarr/bin/bazarr/../libs/urllib3/connectionpool.py", line 793, in urlopen\n    response = self._make_request(\n               ^^^^^^^^^^^^^^^^^^^\n  File "/app/bazarr/bin/bazarr/../libs/urllib3/connectionpool.py", line 496, in _make_request\n    conn.request(\n  File "/app/bazarr/bin/bazarr/../libs/urllib3/connection.py", line 400, in request\n    self.endheaders()\n  File "/usr/lib/python3.12/http/client.py", line 1333, in endheaders\n    self._send_output(message_body, encode_chunked=encode_chunked)\n  File "/usr/lib/python3.12/http/client.py", line 1093, in _send_output\n    self.send(msg)\n  File "/usr/lib/python3.12/http/client.py", line 1037, in send\n    self.connect()\n  File "/app/bazarr/bin/bazarr/../libs/urllib3/connection.py", line 238, in connect\n    self.sock = self._new_conn()\n                ^^^^^^^^^^^^^^^^\n  File "/app/bazarr/bin/bazarr/../libs/urllib3/connection.py", line 207, in _new_conn\n    raise ConnectTimeoutError(\nurllib3.exceptions.ConnectTimeoutError: (<urllib3.connection.HTTPConnection object at 0x7feb7156a660>, \'Connection to ***.***.***.*** timed out. (connect timeout=60)\')\n\nThe above exception was the direct cause of the following exception:\n\nTraceback (most recent call last):\n  File "/app/bazarr/bin/bazarr/../libs/requests/adapters.py", line 486, in send\n    resp = conn.urlopen(\n           ^^^^^^^^^^^^^\n  File "/app/bazarr/bin/bazarr/../libs/urllib3/connectionpool.py", line 847, in urlopen\n    retries = retries.increment(\n              ^^^^^^^^^^^^^^^^^^\n  File "/app/bazarr/bin/bazarr/../libs/urllib3/util/retry.py", line 515, in increment\n    raise MaxRetryError(_pool, url, reason) from reason  # type: ignore[arg-type]\n    ^^^^^^^^^^^^^^^^^^^^^^^^^^^^^^^^^^^^^^^^^^^^^^^^^^^\nurllib3.exceptions.MaxRetryError: HTTPConnectionPool(host=\'***.***.***.***\', port=8989): Max retries exceeded with url: /api/v3/rootfolder?apikey=(removed) (Caused by ConnectTimeoutError(<urllib3.connection.HTTPConnection object at 0x7feb7156a660>, \'Connection to ***.***.***.*** timed out. (connect timeout=60)\'))\n\nDuring handling of the above exception, another exception occurred:\n\nTraceback (most recent call last):\n  File "/app/bazarr/bin/bazarr/sonarr/rootfolder.py", line 22, in get_sonarr_rootfolder\n    rootfolder = requests.get(url_sonarr_api_rootfolder, timeout=int(settings.sonarr.http_timeout), verify=False, headers=HEADERS)\n                 ^^^^^^^^^^^^^^^^^^^^^^^^^^^^^^^^^^^^^^^^^^^^^^^^^^^^^^^^^^^^^^^^^^^^^^^^^^^^^^^^^^^^^^^^^^^^^^^^^^^^^^^^^^^^^^^^^\n  File "/app/bazarr/bin/bazarr/../libs/requests/api.py", line 73, in get\n    return request("get", url, params=params, **kwargs)\n           ^^^^^^^^^^^^^^^^^^^^^^^^^^^^^^^^^^^^^^^^^^^^\n  File "/app/bazarr/bin/bazarr/../libs/reque