2025-02-09 01:23:00|ERROR   |root                            |Error trying to get releases from Github. Connection Error.|'Traceback (most recent call last):\n  File "/app/bazarr/bin/bazarr/../libs/urllib3/connection.py", line 198, in _new_conn\n    sock = connection.create_connection(\n           ^^^^^^^^^^^^^^^^^^^^^^^^^^^^^\n  File "/app/bazarr/bin/bazarr/../custom_libs/subliminal_patch/http.py", line 325, in patched_create_connection\n    return _orig_create_connection(address, *args, **kwargs)\n           ^^^^^^^^^^^^^^^^^^^^^^^^^^^^^^^^^^^^^^^^^^^^^^^^^\n  File "/app/bazarr/bin/bazarr/../libs/urllib3/util/connection.py", line 60, in create_connection\n    for res in socket.getaddrinfo(host, port, family, socket.SOCK_STREAM):\n               ^^^^^^^^^^^^^^^^^^^^^^^^^^^^^^^^^^^^^^^^^^^^^^^^^^^^^^^^^^\n  File "/usr/lib/python3.12/socket.py", line 976, in getaddrinfo\n    for res in _socket.getaddrinfo(host, port, family, type, proto, flags):\n               ^^^^^^^^^^^^^^^^^^^^^^^^^^^^^^^^^^^^^^^^^^^^^^^^^^^^^^^^^^^\nsocket.gaierror: [Errno -3] Try again\n\nThe above exception was the direct cause of the following exception:\n\nTraceback (most recent call last):\n  File "/app/bazarr/bin/bazarr/../libs/urllib3/connectionpool.py", line 793, in urlopen\n    response = self._make_request(\n               ^^^^^^^^^^^^^^^^^^^\n  File "/app/bazarr/bin/bazarr/../libs/urllib3/connectionpool.py", line 491, in _make_request\n    raise new_e\n  File "/app/bazarr/bin/bazarr/../libs/urllib3/connectionpool.py", line 467, in _make_request\n    self._validate_conn(conn)\n  File "/app/bazarr/bin/bazarr/../libs/urllib3/connectionpool.py", line 1099, in _validate_conn\n    conn.connect()\n  File "/app/bazarr/bin/bazarr/../libs/urllib3/connection.py", line 616, in connect\n    self.sock = sock = self._new_conn()\n                       ^^^^^^^^^^^^^^^^\n  File "/app/bazarr/bin/bazarr/../libs/urllib3/connection.py", line 205, in _new_conn\n    raise NameResolutionError(self.host, self, e) from e\nurllib3.exceptions.NameResolutionError: <urllib3.connection.HTTPSConnection object at 0x77236015cc20>: Failed to resolve \'api.github.com\' ([Errno -3] Try again)\n\nThe above exception was the direct cause of the following exception:\n\nTraceback (most recent call last):\n  File "/app/bazarr/bin/bazarr/../libs/requests/adapters.py", line 486, in send\n    resp = conn.urlopen(\n           ^^^^^^^^^^^^^\n  File "/app/bazarr/bin/bazarr/../libs/urllib3/connectionpool.py", line 847, in urlopen\n    retries = retries.increment(\n              ^^^^^^^^^^^^^^^^^^\n  File "/app/bazarr/bin/bazarr/../libs/urllib3/util/retry.py", line 515, in increment\n    raise MaxRetryError(_pool, url, reason) from reason  # type: ignore[arg-type]\n    ^^^^^^^^^^^^^^^^^^^^^^^^^^^^^^^^^^^^^^^^^^^^^^^^^^^\nurllib3.exceptions.MaxRetryError: HTTPSConnectionPool(host=\'api.github.com\', port=443): Max retries exceeded with url: /repos/morpheus65535/Bazarr/releases?per_page=100 (Caused by NameResolutionError("<urllib3.connection.HTTPSConnection object at 0x77236015cc20>: Failed to resolve \'api.github.com\' ([Errno -3] Try again)"))\n\nDuring handling of the above exception, another exception occurred:\n\nTraceback (most recent call last):\n  File "/app/bazarr/bin/bazarr/app/check_update.py", line 28, in check_releases\n    r = requests.get(url_releases, allow_redirects=True, timeout=15)\n        ^^^^^^^^^^^^^^^^^^^^^^^^^^^^^^^^^^^^^^^^^^^^^^^^^^^^^^^^^^^^\n  File "/app/bazarr/bin/bazarr/../libs/requests/api.py", line 73, in get\n    return request("get", url, params=params, **kwargs)\n           ^^^^^^^^^^^^^^^^^^^^^^^^^^^^^^^^^^^^^^^^^^^^\n  File "/app/bazarr/bin/bazarr/../libs/requests/api.py", line 59, in request\n    return session.request(method=method, url=url, **kwargs)\n           ^^^^^^^^^^^^^^^^^^^^^^^^^^^^^^^^^^^^^^^^^^^^^^^^^\n  File "/app/bazarr/bin/bazarr/../libs/requests/sessions.py", line 589, in request\n    resp = self.send(prep, **send_kwargs)\n           ^^^^^^^^^^^^^^^^^^^^^^^^^^^^^^\n  File "/app/bazarr/bin/bazarr/../libs/requests/sessions.py", line 703, in send\n    r = adapter.send(request, **kwargs)\n        ^^^^^^^^^^^^^^^^^^^^^^^^^^^^^^^\n  File "/app/bazarr/bin/bazarr/../libs/requests/adapters.py", line 519, in send\n    raise ConnectionError(e, request=request)\nrequests.exceptions.ConnectionError: HTTPSConnectionPool(host=\'api.github.com\', port=443): Max retries exceeded with url: /repos/morpheus65535/Bazarr/releases?per_page=100 (Caused by NameResolutionError("<urllib3.connection.HTTPSConnection object at 0x77236015cc20>: Failed to resolve \'api.github.com\' ([Errno -3] Try again)"))'|
2025-02-09 03:55:14|ERROR   |root                            |Error trying to get announcements from Github. Connection Error.|'Traceback (most recent call last):\n  File "/app/bazarr/bin/bazarr/../libs/urllib3/connection.py", line 198, in _new_conn\n    sock = connection.create_connection(\n           ^^^^^^^^^^^^^^^^^^^^^^^^^^^^^\n  File "/app/bazarr/bin/bazarr/../custom_libs/subliminal_patch/http.py", line 325, in patched_create_connection\n    return _orig_create_connection(address, *args, **kwargs)\n           ^^^^^^^^^^^^^^^^^^^^^^^^^^^^^^^^^^^^^^^^^^^^^^^^^\n  File "/app/bazarr/bin/bazarr/../libs/urllib3/util/connection.py", line 60, in create_connection\n    for res in socket.getaddrinfo(host, port, family, socket.SOCK_STREAM):\n               ^^^^^^^^^^^^^^^^^^^^^^^^^^^^^^^^^^^^^^^^^^^^^^^^^^^^^^^^^^\n  File "/usr/lib/python3.12/socket.py", line 976, in getaddrinfo\n    for res in _socket.getaddrinfo(host, port, family, type, proto, flags):\n               ^^^^^^^^^^^^^^^^^^^^^^^^^^^^^^^^^^^^^^^^^^^^^^^^^^^^^^^^^^^\nsocket.gaierror: [Errno -3] Try again\n\nThe above exception was the direct cause of the following exception:\n\nTraceback (most recent call last):\n  File "/app/bazarr/bin/bazarr/../libs/urllib3/connectionpool.py", line 793, in urlopen\n    response = self._make_request(\n               ^^^^^^^^^^^^^^^^^^^\n  File "/app/bazarr/bin/bazarr/../libs/urllib3/connectionpool.py", line 491, in _make_request\n    raise new_e\n  File "/app/bazarr/bin/bazarr/../libs/urllib3/connectionpool.py", line 467, in _make_request\n    self._validate_conn(conn)\n  File "/app/bazarr/bin/bazarr/../libs/urllib3/connectionpool.py", line 1099, in _validate_conn\n    conn.connect()\n  File "/app/bazarr/bin/bazarr/../libs/urllib3/connection.py", line 616, in connect\n    self.sock = sock = self._new_conn()\n                       ^^^^^^^^^^^^^^^^\n  File "/app/bazarr/bin/bazarr/../libs/urllib3/connection.py", line 205, in _new_conn\n    raise NameResolutionError(self.host, self, e) from e\nurllib3.exceptions.NameResolutionError: <urllib3.connection.HTTPSConnection object at 0x77235ed87bc0>: Failed to resolve \'raw.githubusercontent.com\' ([Errno -3] Try again)\n\nThe above exception was the direct cause of the following exception:\n\nTraceback (most recent call last):\n  File "/app/bazarr/bin/bazarr/../libs/requests/adapters.py", line 486, in send\n    resp = conn.urlopen(\n           ^^^^^^^^^^^^^\n  File "/app/bazarr/bin/bazarr/../libs/urllib3/connectionpool.py", line 847, in urlopen\n    retries = retries.increment(\n              ^^^^^^^^^^^^^^^^^^\n  File "/app/bazarr/bin/bazarr/../libs/urllib3/util/retry.py", line 515, in increment\n    raise MaxRetryError(_pool, url, reason) from reason  # type: ignore[arg-type]\n    ^^^^^^^^^^^^^^^^^^^^^^^^^^^^^^^^^^^^^^^^^^^^^^^^^^^\nurllib3.exceptions.MaxRetryError: HTTPSConnectionPool(host=\'raw.githubusercontent.com\', port=443): Max retries exceeded with url: /morpheus65535/bazarr-binaries/master/announcements.json (Caused by NameResolutionError("<urllib3.connection.HTTPSConnection object at 0x77235ed87bc0>: Failed to resolve \'raw.githubusercontent.com\' ([Errno -3] Try again)"))\n\nDuring handling of the above exception, another exception occurred:\n\nTraceback (most recent call last):\n  File "/app/bazarr/bin/bazarr/app/announcements.py", line 46, in get_announcements_to_file\n    r = requests.get("https://raw.githubusercontent.com/morpheus65535/bazarr-binaries/master/announcements.json",\n        ^^^^^^^^^^^^^^^^^^^^^^^^^^^^^^^^^^^^^^^^^^^^^^^^^^^^^^^^^^^^^^^^^^^^^^^^^^^^^^^^^^^^^^^^^^^^^^^^^^^^^^^^^\n  File "/app/bazarr/bin/bazarr/../libs/requests/api.py", line 73, in get\n    return request("get", url, params=params, **kwargs)\n           ^^^^^^^^^^^^^^^^^^^^^^^^^^^^^^^^^^^^^^^^^^^^\n  File "/app/bazarr/bin/bazarr/../libs/requests/api.py", line 59, in request\n    return session.request(method=method, url=url, **kwargs)\n           ^^^^^^^^^^^^^^^^^^^^^^^^^^^^^^^^^^^^^^^^^^^^^^^^^\n  File "/app/bazarr/bin/bazarr/../libs/requests/sessions.py", line 589, in request\n    resp = self.send(prep, **send_kwargs)\n           ^^^^^^^^^^^^^^^^^^^^^^^^^^^^^^\n  File "/app/bazarr/bin/bazarr/../libs/requests/sessions.py", line 703, in send\n    r = adapter.send(request, **kwargs)\n        ^^^^^^^^^^^^^^^^^^^^^^^^^^^^^^^\n  File "/app/bazarr/bin/bazarr/../libs/requests/adapters.py", line 519, in send\n    raise ConnectionError(e, request=request)\nrequests.exceptions.ConnectionError: HTTPSConnectionPool(host=\'raw.githubusercontent.com\', port=443): Max retries exceeded with url: /morpheus65535/bazarr-binaries/master/announcements.json (Caused by NameResolutionError("<urllib3.connection.HTTPSConnection object at 0x77235ed87bc0>: Failed to resolve \'raw.githubusercontent.com\' ([Errno -3] Try again)"))'|
2025-02-09 04:00:04|INFO    |root                            |BAZARR All existing movie subtitles indexed from disk.|
2025-02-09 04:00:14|INFO    |root                            |BAZARR All existing episode subtitles indexed from disk.|
2025-02-09 04:06:56|INFO    |root                            |BAZARR Search is throttled by adaptive search for this movie /local_media/movies/James Acaster Cold Lasagne Hate Myself 1999 (2020)/James Acaster Cold Lasagne Hate Myself 1999 2020 1080p WEBRip YTS MX.mp4 and language: en|
2025-02-09 04:06:56|INFO    |root                            |BAZARR Search is throttled by adaptive search for this movie /local_media/movies/Jatt & Juliet (2012)/Jatt and Juliet (2012) (Punjabi Movie) 1CD DVDSCR-Rip XviD TeamTNT Exclusive.avi and language: en|
2025-02-09 04:06:56|INFO    |root                            |BAZARR Finished searching for missing Movies Subtitles. Check History for more information.|
2025-02-09 04:23:00|ERROR   |root                            |Error trying to get releases from Github. Connection Error.|'Traceback (most recent call last):\n  File "/app/bazarr/bin/bazarr/../libs/urllib3/connection.py", line 198, in _new_conn\n    sock = connection.create_connection(\n           ^^^^^^^^^^^^^^^^^^^^^^^^^^^^^\n  File "/app/bazarr/bin/bazarr/../custom_libs/subliminal_patch/http.py", line 325, in patched_create_connection\n    return _orig_create_connection(address, *args, **kwargs)\n           ^^^^^^^^^^^^^^^^^^^^^^^^^^^^^^^^^^^^^^^^^^^^^^^^^\n  File "/app/bazarr/bin/bazarr/../libs/urllib3/util/connection.py", line 60, in create_connection\n    for res in socket.getaddrinfo(host, port, family, socket.SOCK_STREAM):\n               ^^^^^^^^^^^^^^^^^^^^^^^^^^^^^^^^^^^^^^^^^^^^^^^^^^^^^^^^^^\n  File "/usr/lib/python3.12/socket.py", line 976, in getaddrinfo\n    for res in _socket.getaddrinfo(host, port, family, type, proto, flags):\n               ^^^^^^^^^^^^^^^^^^^^^^^^^^^^^^^^^^^^^^^^^^^^^^^^^^^^^^^^^^^\nsocket.gaierror: [Errno -3] Try again\n\nThe above exception was the direct cause of the following exception:\n\nTraceback (most recent call last):\n  File "/app/bazarr/bin/bazarr/../libs/urllib3/connectionpool.py", line 793, in urlopen\n    response = self._make_request(\n               ^^^^^^^^^^^^^^^^^^^\n  File "/app/bazarr/bin/bazarr/../libs/urllib3/connectionpool.py", line 491, in _make_request\n    raise new_e\n  File "/app/bazarr/bin/bazarr/../libs/urllib3/connectionpool.py", line 467, in _make_request\n    self._validate_conn(conn)\n  File "/app/bazarr/bin/bazarr/../libs/urllib3/connectionpool.py", line 1099, in _validate_conn\n    conn.connect()\n  File "/app/bazarr/bin/bazarr/../libs/urllib3/connection.py", line 616, in connect\n    self.sock = sock = self._new_conn()\n                       ^^^^^^^^^^^^^^^^\n  File "/app/bazarr/bin/bazarr/../libs/urllib3/connection.py", line 205, in _new_conn\n    raise NameResolutionError(self.host, self, e) from e\nurllib3.exceptions.NameResolutionError: <urllib3.connection.HTTPSConnection object at 0x77235ed7db50>: Failed to resolve \'api.github.com\' ([Errno -3] Try again)\n\nThe above exception was the direct cause of the following exception:\n\nTraceback (most recent call last):\n  File "/app/bazarr/bin/bazarr/../libs/requests/adapters.py", line 486, in send\n    resp = conn.urlopen(\n           ^^^^^^^^^^^^^\n  File "/app/bazarr/bin/bazarr/../libs/urllib3/connectionpool.py", line 847, in urlopen\n    retries = retries.increment(\n              ^^^^^^^^^^^^^^^^^^\n  File "/app/bazarr/bin/bazarr/../libs/urllib3/util/retry.py", line 515, in increment\n    raise MaxRetryError(_pool, url, reason) from reason  # type: ignore[arg-type]\n    ^^^^^^^^^^^^^^^^^^^^^^^^^^^^^^^^^^^^^^^^^^^^^^^^^^^\nurllib3.exceptions.MaxRetryError: HTTPSConnectionPool(host=\'api.github.com\', port=443): Max retries exceeded with url: /repos/morpheus65535/Bazarr/releases?per_page=100 (Caused by NameResolutionError("<urllib3.connection.HTTPSConnection object at 0x77235ed7db50>: Failed to resolve \'api.github.com\' ([Errno -3] Try again)"))\n\nDuring handling of the above exception, another exception occurred:\n\nTraceback (most recent call last):\n  File "/app/bazarr/bin/bazarr/app/check_update.py", line 28, in check_releases\n    r = requests.get(url_releases, allow_redirects=True, timeout=15)\n        ^^^^^^^^^^^^^^^^^^^^^^^^^^^^^^^^^^^^^^^^^^^^^^^^^^^^^^^^^^^^\n  File "/app/bazarr/bin/bazarr/../libs/requests/api.py", line 73, in get\n    return request("get", url, params=params, **kwargs)\n           ^^^^^^^^^^^^^^^^^^^^^^^^^^^^^^^^^^^^^^^^^^^^\n  File "/app/bazarr/bin/bazarr/../libs/requests/api.py", line 59, in request\n    return session.request(method=method, url=url, **kwargs)\n           ^^^^^^^^^^^^^^^^^^^^^^^^^^^^^^^^^^^^^^^^^^^^^^^^^\n  File "/app/bazarr/bin/bazarr/../libs/requests/sessions.py", line 589, in request\n    resp = self.send(prep, **send_kwargs)\n           ^^^^^^^^^^^^^^^^^^^^^^^^^^^^^^\n  File "/app/bazarr/bin/bazarr/../libs/requests/sessions.py", line 703, in send\n    r = adapter.send(request, **kwargs)\n        ^^^^^^^^^^^^^^^^^^^^^^^^^^^^^^^\n  File "/app/bazarr/bin/bazarr/../libs/requests/adapters.py", line 519, in send\n    raise ConnectionError(e, request=request)\nrequests.exceptions.ConnectionError: HTTPSConnectionPool(host=\'api.github.com\', port=443): Max retries exceeded with url: /repos/morpheus65535/Bazarr/releases?per_page=100 (Caused by NameResolutionError("<urllib3.connection.HTTPSConnection object at 0x77235ed7db50>: Failed to resolve \'api.github.com\' ([Errno -3] Try again)"))'|
2025-02-09 04:26:56|INFO    |root                            |BAZARR Finished searching for missing Series Subtitles. Check History for more information.|
2025-02-09 07:23:00|ERROR   |root                            |Error trying to get releases from Github. Connection Error.|'Traceback (most recent call last):\n  File "/app/bazarr/bin/bazarr/../libs/urllib3/connection.py", line 198, in _new_conn\n    sock = connection.create_connection(\n           ^^^^^^^^^^^^^^^^^^^^^^^^^^^^^\n  File "/app/bazarr/bin/bazarr/../custom_libs/subliminal_patch/http.py", line 325, in patched_create_connection\n    return _orig_create_connection(address, *args, **kwargs)\n           ^^^^^^^^^^^^^^^^^^^^^^^^^^^^^^^^^^^^^^^^^^^^^^^^^\n  File "/app/bazarr/bin/bazarr/../libs/urllib3/util/connection.py", line 60, in create_connection\n    for res in socket.getaddrinfo(host, port, family, socket.SOCK_STREAM):\n               ^^^^^^^^^^^^^^^^^^^^^^^^^^^^^^^^^^^^^^^^^^^^^^^^^^^^^^^^^^\n  File "/usr/lib/python3.12/socket.py", line 976, in getaddrinfo\n    for res in _socket.getaddrinfo(host, port, family, type, proto, flags):\n               ^^^^^^^^^^^^^^^^^^^^^^^^^^^^^^^^^^^^^^^^^^^^^^^^^^^^^^^^^^^\nsocket.gaierror: [Errno -3] Try again\n\nThe above exception was the direct cause of the following exception:\n\nTraceback (most recent call last):\n  File "/app/bazarr/bin/bazarr/../libs/urllib3/connectionpool.py", line 793, in urlopen\n    response = self._make_request(\n               ^^^^^^^^^^^^^^^^^^^\n  File "/app/bazarr/bin/bazarr/../libs/urllib3/connectionpool.py", line 491, in _make_request\n    raise new_e\n  File "/app/bazarr/bin/bazarr/../libs/urllib3/connectionpool.py", line 467, in _make_request\n    self._validate_conn(conn)\n  File "/app/bazarr/bin/bazarr/../libs/urllib3/connectionpool.py", line 1099, in _validate_conn\n    conn.connect()\n  File "/app/bazarr/bin/bazarr/../libs/urllib3/connection.py", line 616, in connect\n    self.sock = sock = self._new_conn()\n                       ^^^^^^^^^^^^^^^^\n  File "/app/bazarr/bin/bazarr/../libs/urllib3/connection.py", line 205, in _new_conn\n    raise NameResolutionError(self.host, self, e) from e\nurllib3.exceptions.NameResolutionError: <urllib3.connection.HTTPSConnection object at 0x77235e1e5850>: Failed to resolve \'api.github.com\' ([Errno -3] Try again)\n\nThe above exception was the direct cause of the following exception:\n\nTraceback (most recent call last):\n  File "/app/bazarr/bin/bazarr/../libs/requests/adapters.py", line 486, in send\n    resp = conn.urlopen(\n           ^^^^^^^^^^^^^\n  File "/app/bazarr/bin/bazarr/../libs/urllib3/connectionpool.py", line 847, in urlopen\n    retries = retries.increment(\n              ^^^^^^^^^^^^^^^^^^\n  File "/app/bazarr/bin/bazarr/../libs/urllib3/util/retry.py", line 515, in increment\n    raise MaxRetryError(_pool, url, reason) from reason  # type: ignore[arg-type]\n    ^^^^^^^^^^^^^^^^^^^^^^^^^^^^^^^^^^^^^^^^^^^^^^^^^^^\nurllib3.exceptions.MaxRetryError: HTTPSConnectionPool(host=\'api.github.com\', port=443): Max retries exceeded with url: /repos/morpheus65535/Bazarr/releases?per_page=100 (Caused by NameResolutionError("<urllib3.connection.HTTPSConnection object at 0x77235e1e5850>: Failed to resolve \'api.github.com\' ([Errno -3] Try again)"))\n\nDuring handling of the above exception, another exception occurred:\n\nTraceback (most recent call last):\n  File "/app/bazarr/bin/bazarr/app/check_update.py", line 28, in check_releases\n    r = requests.get(url_releases, allow_redirects=True, timeout=15)\n        ^^^^^^^^^^^^^^^^^^^^^^^^^^^^^^^^^^^^^^^^^^^^^^^^^^^^^^^^^^^^\n  File "/app/bazarr/bin/bazarr/../libs/requests/api.py", line 73, in get\n    return request("get", url, params=params, **kwargs)\n           ^^^^^^^^^^^^^^^^^^^^^^^^^^^^^^^^^^^^^^^^^^^^\n  File "/app/bazarr/bin/bazarr/../libs/requests/api.py", line 59, in request\n    return session.request(method=method, url=url, **kwargs)\n           ^^^^^^^^^^^^^^^^^^^^^^^^^^^^^^^^^^^^^^^^^^^^^^^^^\n  File "/app/bazarr/bin/bazarr/../libs/requests/sessions.py", line 589, in request\n    resp = self.send(prep, **send_kwargs)\n           ^^^^^^^^^^^^^^^^^^^^^^^^^^^^^^\n  File "/app/bazarr/bin/bazarr/../libs/requests/sessions.py", line 703, in send\n    r = adapter.send(request, **kwargs)\n        ^^^^^^^^^^^^^^^^^^^^^^^^^^^^^^^\n  File "/app/bazarr/bin/bazarr/../libs/requests/adapters.py", line 519, in send\n    raise ConnectionError(e, request=request)\nrequests.exceptions.ConnectionError: HTTPSConnectionPool(host=\'api.github.com\', port=443): Max retries exceeded with url: /repos/morpheus65535/Bazarr/releases?per_page=100 (Caused by NameResolutionError("<urllib3.connection.HTTPSConnection object at 0x77235e1e5850>: Failed to resolve \'api.github.com\' ([Errno -3] Try again)"))'|
2025-02-09 09:55:14|ERROR   |root                            |Error trying to get announcements from Github. Connection Error.|'Traceback (most recent call last):\n  File "/app/bazarr/bin/bazarr/../libs/urllib3/connection.py", line 198, in _new_conn\n    sock = connection.create_connection(\n           ^^^^^^^^^^^^^^^^^^^^^^^^^^^^^\n  File "/app/bazarr/bin/bazarr/../custom_libs/subliminal_patch/http.py", line 325, in patched_create_connection\n    return _orig_create_connection(address, *args, **kwargs)\n           ^^^^^^^^^^^^^^^^^^^^^^^^^^^^^^^^^^^^^^^^^^^^^^^^^\n  File "/app/bazarr/bin/bazarr/../libs/urllib3/util/connection.py", line 60, in create_connection\n    for res in socket.getaddrinfo(host, port, family, socket.SOCK_STREAM):\n               ^^^^^^^^^^^^^^^^^^^^^^^^^^^^^^^^^^^^^^^^^^^^^^^^^^^^^^^^^^\n  File "/usr/lib/python3.12/socket.py", line 976, in getaddrinfo\n    for res in _socket.getaddrinfo(host, port, family, type, proto, flags):\n               ^^^^^^^^^^^^^^^^^^^^^^^^^^^^^^^^^^^^^^^^^^^^^^^^^^^^^^^^^^^\nsocket.gaierror: [Errno -3] Try again\n\nThe above exception was the direct cause of the following exception:\n\nTraceback (most recent call last):\n  File "/app/bazarr/bin/bazarr/../libs/urllib3/connectionpool.py", line 793, in urlopen\n    response = self._make_request(\n               ^^^^^^^^^^^^^^^^^^^\n  File "/app/bazarr/bin/bazarr/../libs/urllib3/connectionpool.py", line 491, in _make_request\n    raise new_e\n  File "/app/bazarr/bin/bazarr/../libs/urllib3/connectionpool.py", line 467, in _make_request\n    self._validate_conn(conn)\n  File "/app/bazarr/bin/bazarr/../libs/urllib3/connectionpool.py", line 1099, in _validate_conn\n    conn.connect()\n  File "/app/bazarr/bin/bazarr/../libs/urllib3/connection.py", line 616, in connect\n    self.sock = sock = self._new_conn()\n                       ^^^^^^^^^^^^^^^^\n  File "/app/bazarr/bin/bazarr/../libs/urllib3/connection.py", line 205, in _new_conn\n    raise NameResolutionError(self.host, self, e) from e\nurllib3.exceptions.NameResolutionError: <urllib3.connection.HTTPSConnection object at 0x77235e10b1a0>: Failed to resolve \'raw.githubusercontent.com\' ([Errno -3] Try again)\n\nThe above exception was the direct cause of the following exception:\n\nTraceback (most recent call last):\n  File "/app/bazarr/bin/bazarr/../libs/requests/adapters.py", line 486, in send\n    resp = conn.urlopen(\n           ^^^^^^^^^^^^^\n  File "/app/bazarr/bin/bazarr/../libs/urllib3/connectionpool.py", line 847, in urlopen\n    retries = retries.increment(\n              ^^^^^^^^^^^^^^^^^^\n  File "/app/bazarr/bin/bazarr/../libs/urllib3/util/retry.py", line 515, in increment\n    raise MaxRetryError(_pool, url, reason) from reason  # type: ignore[arg-type]\n    ^^^^^^^^^^^^^^^^^^^^^^^^^^^^^^^^^^^^^^^^^^^^^^^^^^^\nurllib3.exceptions.MaxRetryError: HTTPSConnectionPool(host=\'raw.githubusercontent.com\', port=443): Max retries exceeded with url: /morpheus65535/bazarr-binaries/master/announcements.json (Caused by NameResolutionError("<urllib3.connection.HTTPSConnection object at 0x77235e10b1a0>: Failed to resolve \'raw.githubusercontent.com\' ([Errno -3] Try again)"))\n\nDuring handling of the above exception, another exception occurred:\n\nTraceback (most recent call last):\n  File "/app/bazarr/bin/bazarr/app/announcements.py", line 46, in get_announcements_to_file\n    r = requests.get("https://raw.githubusercontent.com/morpheus65535/bazarr-binaries/master/announcements.json",\n        ^^^^^^^^^^^^^^^^^^^^^^^^^^^^^^^^^^^^^^^^^^^^^^^^^^^^^^^^^^^^^^^^^^^^^^^^^^^^^^^^^^^^^^^^^^^^^^^^^^^^^^^^^\n  File "/app/bazarr/bin/bazarr/../libs/requests/api.py", line 73, in get\n    return request("get", url, params=params, **kwargs)\n           ^^^^^^^^^^^^^^^^^^^^^^^^^^^^^^^^^^^^^^^^^^^^\n  File "/app/bazarr/bin/bazarr/../libs/requests/api.py", line 59, in request\n    return session.request(method=method, url=url, **kwargs)\n           ^^^^^^^^^^^^^^^^^^^^^^^^^^^^^^^^^^^^^^^^^^^^^^^^^\n  File "/app/bazarr/bin/bazarr/../libs/requests/sessions.py", line 589, in request\n    resp = self.send(prep, **send_kwargs)\n           ^^^^^^^^^^^^^^^^^^^^^^^^^^^^^^\n  File "/app/bazarr/bin/bazarr/../libs/requests/sessions.py", line 703, in send\n    r = adapter.send(request, **kwargs)\n        ^^^^^^^^^^^^^^^^^^^^^^^^^^^^^^^\n  File "/app/bazarr/bin/bazarr/../libs/requests/adapters.py", line 519, in send\n    raise ConnectionError(e, request=request)\nrequests.exceptions.ConnectionError: HTTPSConnectionPool(host=\'raw.githubusercontent.com\', port=443): Max retries exceeded with url: /morpheus65535/bazarr-binaries/master/announcements.json (Caused by NameResolutionError("<urllib3.connection.HTTPSConnection object at 0x77235e10b1a0>: Failed to resolve \'raw.githubusercontent.com\' ([Errno -3] Try again)"))'|
2025-02-09 10:06:56|INFO    |root                            |BAZARR Search is throttled by adaptive search for this movie /local_media/movies/James Acaster Cold Lasagne Hate Myself 1999 (2020)/James Acaster Cold Lasagne Hate Myself 1999 2020 1080p WEBRip YTS MX.mp4 and language: en|
2025-02-09 10:06:56|INFO    |root                            |BAZARR Search is throttled by adaptive search for this movie /local_media/movies/Jatt & Juliet (2012)/Jatt and Juliet (2012) (Punjabi Movie) 1CD DVDSCR-Rip XviD TeamTNT Exclusive.avi and language: en|
2025-02-09 10:06:56|INFO    |root                            |BAZARR Finished searching for missing Movies Subtitles. Check History for more information.|
2025-02-09 10:23:00|ERROR   |root                            |Error trying to get releases from Github. Connection Error.|'Traceback (most recent call last):\n  File "/app/bazarr/bin/bazarr/../libs/urllib3/connection.py", line 198, in _new_conn\n    sock = connection.create_connection(\n           ^^^^^^^^^^^^^^^^^^^^^^^^^^^^^\n  File "/app/bazarr/bin/bazarr/../custom_libs/subliminal_patch/http.py", line 325, in patched_create_connection\n    return _orig_create_connection(address, *args, **kwargs)\n           ^^^^^^^^^^^^^^^^^^^^^^^^^^^^^^^^^^^^^^^^^^^^^^^^^\n  File "/app/bazarr/bin/bazarr/../libs/urllib3/util/connection.py", line 60, in create_connection\n    for res in socket.getaddrinfo(host, port, family, socket.SOCK_STREAM):\n               ^^^^^^^^^^^^^^^^^^^^^^^^^^^^^^^^^^^^^^^^^^^^^^^^^^^^^^^^^^\n  File "/usr/lib/python3.12/socket.py", line 976, in getaddrinfo\n    for res in _socket.getaddrinfo(host, port, family, type, proto, flags):\n               ^^^^^^^^^^^^^^^^^^^^^^^^^^^^^^^^^^^^^^^^^^^^^^^^^^^^^^^^^^^\nsocket.gaierror: [Errno -3] Try again\n\nThe above exception was the direct cause of the following exception:\n\nTraceback (most recent call last):\n  File "/app/bazarr/bin/bazarr/../libs/urllib3/connectionpool.py", line 793, in urlopen\n    response = self._make_request(\n               ^^^^^^^^^^^^^^^^^^^\n  File "/app/bazarr/bin/bazarr/../libs/urllib3/connectionpool.py", line 491, in _make_request\n    raise new_e\n  File "/app/bazarr/bin/bazarr/../libs/urllib3/connectionpool.py", line 467, in _make_request\n    self._validate_conn(conn)\n  File "/app/bazarr/bin/bazarr/../libs/urllib3/connectionpool.py", line 1099, in _validate_conn\n    conn.connect()\n  File "/app/bazarr/bin/bazarr/../libs/urllib3/connection.py", line 616, in connect\n    self.sock = sock = self._new_conn()\n                       ^^^^^^^^^^^^^^^^\n  File "/app/bazarr/bin/bazarr/../libs/urllib3/connection.py", line 205, in _new_conn\n    raise NameResolutionError(self.host, self, e) from e\nurllib3.exceptions.NameResolutionError: <urllib3.connection.HTTPSConnection object at 0x77235e10b500>: Failed to resolve \'api.github.com\' ([Errno -3] Try again)\n\nThe above exception was the direct cause of the following exception:\n\nTraceback (most recent call last):\n  File "/app/bazarr/bin/bazarr/../libs/requests/adapters.py", line 486, in send\n    resp = conn.urlopen(\n           ^^^^^^^^^^^^^\n  File "/app/bazarr/bin/bazarr/../libs/urllib3/connectionpool.py", line 847, in urlopen\n    retries = retries.increment(\n              ^^^^^^^^^^^^^^^^^^\n  File "/app/bazarr/bin/bazarr/../libs/urllib3/util/retry.py", line 515, in increment\n    raise MaxRetryError(_pool, url, reason) from reason  # type: ignore[arg-type]\n    ^^^^^^^^^^^^^^^^^^^^^^^^^^^^^^^^^^^^^^^^^^^^^^^^^^^\nurllib3.exceptions.MaxRetryError: HTTPSConnectionPool(host=\'api.github.com\', port=443): Max retries exceeded with url: /repos/morpheus65535/Bazarr/releases?per_page=100 (Caused by NameResolutionError("<urllib3.connection.HTTPSConnection object at 0x77235e10b500>: Failed to resolve \'api.github.com\' ([Errno -3] Try again)"))\n\nDuring handling of the above exception, another exception occurred:\n\nTraceback (most recent call last):\n  File "/app/bazarr/bin/bazarr/app/check_update.py", line 28, in check_releases\n    r = requests.get(url_releases, allow_redirects=True, timeout=15)\n        ^^^^^^^^^^^^^^^^^^^^^^^^^^^^^^^^^^^^^^^^^^^^^^^^^^^^^^^^^^^^\n  File "/app/bazarr/bin/bazarr/../libs/requests/api.py", line 73, in get\n    return request("get", url, params=params, **kwargs)\n           ^^^^^^^^^^^^^^^^^^^^^^^^^^^^^^^^^^^^^^^^^^^^\n  File "/app/bazarr/bin/bazarr/../libs/requests/api.py", line 59, in request\n    return session.request(method=method, url=url, **kwargs)\n           ^^^^^^^^^^^^^^^^^^^^^^^^^^^^^^^^^^^^^^^^^^^^^^^^^\n  File "/app/bazarr/bin/bazarr/../libs/requests/sessions.py", line 589, in request\n    resp = self.send(prep, **send_kwargs)\n           ^^^^^^^^^^^^^^^^^^^^^^^^^^^^^^\n  File "/app/bazarr/bin/bazarr/../libs/requests/sessions.py", line 703, in send\n    r = adapter.send(request, **kwargs)\n        ^^^^^^^^^^^^^^^^^^^^^^^^^^^^^^^\n  File "/app/bazarr/bin/bazarr/../libs/requests/adapters.py", line 519, in send\n    raise ConnectionError(e, request=request)\nrequests.exceptions.ConnectionError: HTTPSConnectionPool(host=\'api.github.com\', port=443): Max retries exceeded with url: /repos/morpheus65535/Bazarr/releases?per_page=100 (Caused by NameResolutionError("<urllib3.connection.HTTPSConnection object at 0x77235e10b500>: Failed to resolve \'api.github.com\' ([Errno -3] Try again)"))'|
2025-02-09 10:26:56|INFO    |root                            |BAZARR Finished searching for missing Series Subtitles. Check History for more information.|
2025-02-09 10:31:59|INFO    |root                            |BAZARR Finished searching for Subtitles to upgrade. Check History for more information.|
